<?xml version="1.0" encoding="UTF-8"?>
<!-- Generated by org.testng.reporters.JUnitReportReporter -->
<testsuite hostname="kadamba-desktop" name="TestReport.Login_Test" tests="8" failures="0" timestamp="1 Aug 2018 12:04:33 GMT" time="36.655" errors="1">
  <testcase name="Test5" time="4.312" classname="TestReport.Login_Test"/>
  <testcase name="Test2" time="13.912" classname="TestReport.Login_Test">
    <error type="java.lang.AssertionError" message="Not a Home Page expected [http://192.168.2.17:5000/#/] but found [http://192.168.2.17:5000/]">
      <![CDATA[java.lang.AssertionError: Not a Home Page expected [http://192.168.2.17:5000/#/] but found [http://192.168.2.17:5000/]
	at org.testng.Assert.fail(Assert.java:94)
	at org.testng.Assert.failNotEquals(Assert.java:494)
	at org.testng.Assert.assertEquals(Assert.java:123)
	at org.testng.Assert.assertEquals(Assert.java:176)
	at Flow.Login.validLogin(Login.java:42)
	at TestReport.Login_Test.Test2(Login_Test.java:118)
	at sun.reflect.NativeMethodAccessorImpl.invoke0(Native Method)
	at sun.reflect.NativeMethodAccessorImpl.invoke(NativeMethodAccessorImpl.java:62)
	at sun.reflect.DelegatingMethodAccessorImpl.invoke(DelegatingMethodAccessorImpl.java:43)
	at java.lang.reflect.Method.invoke(Method.java:498)
	at org.testng.internal.MethodInvocationHelper.invokeMethod(MethodInvocationHelper.java:80)
	at org.testng.internal.Invoker.invokeMethod(Invoker.java:714)
	at org.testng.internal.Invoker.invokeTestMethod(Invoker.java:901)
	at org.testng.internal.Invoker.invokeTestMethods(Invoker.java:1231)
	at org.testng.internal.TestMethodWorker.invokeTestMethods(TestMethodWorker.java:127)
	at org.testng.internal.TestMethodWorker.run(TestMethodWorker.java:111)
	at org.testng.TestRunner.privateRun(TestRunner.java:767)
	at org.testng.TestRunner.run(TestRunner.java:617)
	at org.testng.SuiteRunner.runTest(SuiteRunner.java:334)
	at org.testng.SuiteRunner.runSequentially(SuiteRunner.java:329)
	at org.testng.SuiteRunner.privateRun(SuiteRunner.java:291)
	at org.testng.SuiteRunner.run(SuiteRunner.java:240)
	at org.testng.SuiteRunnerWorker.runSuite(SuiteRunnerWorker.java:52)
	at org.testng.SuiteRunnerWorker.run(SuiteRunnerWorker.java:86)
	at org.testng.TestNG.runSuitesSequentially(TestNG.java:1198)
	at org.testng.TestNG.runSuitesLocally(TestNG.java:1123)
	at org.testng.TestNG.run(TestNG.java:1031)
	at org.testng.remote.AbstractRemoteTestNG.run(AbstractRemoteTestNG.java:114)
	at org.testng.remote.RemoteTestNG.initAndRun(RemoteTestNG.java:251)
	at org.testng.remote.RemoteTestNG.main(RemoteTestNG.java:77)
]]>
    </error>
  </testcase> <!-- Test2 -->
  <testcase name="Test1" time="2.068" classname="TestReport.Login_Test"/>
  <testcase name="Test7" time="2.183" classname="TestReport.Login_Test"/>
  <testcase name="Test4" time="2.460" classname="TestReport.Login_Test"/>
  <testcase name="Test6" time="3.619" classname="TestReport.Login_Test"/>
  <testcase name="Test3" time="2.917" classname="TestReport.Login_Test"/>
  <testcase name="Test8" time="5.184" classname="TestReport.Login_Test"/>
</testsuite> <!-- TestReport.Login_Test -->
